<sdf version='1.9'>
  <world name='frosty_world'>
    <plugin name='ignition::gazebo::systems::TriggeredPublisher' filename='libignition-gazebo-triggered-publisher-system.so'>
      <input type='ignition.msgs.Int32' topic='/keyboard/keypress'>
        <match field='data'>16777235</match>
      </input>
      <output type='ignition.msgs.Twist' topic='/cmd_vel'>linear: {x: 0.5}, angular: {z: 0.0}</output>
    </plugin>
    <plugin name='ignition::gazebo::systems::TriggeredPublisher' filename='libignition-gazebo-triggered-publisher-system.so'>
      <input type='ignition.msgs.Int32' topic='/keyboard/keypress'>
        <match field='data'>16777237</match>
      </input>
      <output type='ignition.msgs.Twist' topic='/cmd_vel'>linear: {x: -0.5}, angular: {z: 0.0}</output>
    </plugin>
    <plugin name='ignition::gazebo::systems::TriggeredPublisher' filename='libignition-gazebo-triggered-publisher-system.so'>
      <input type='ignition.msgs.Int32' topic='/keyboard/keypress'>
        <match field='data'>16777236</match>
      </input>
      <output type='ignition.msgs.Twist' topic='/cmd_vel'>linear: {x: 0.0}, angular: {z: -0.5}</output>
    </plugin>
    <plugin name='ignition::gazebo::systems::TriggeredPublisher' filename='libignition-gazebo-triggered-publisher-system.so'>
      <input type='ignition.msgs.Int32' topic='/keyboard/keypress'>
        <match field='data'>16777234</match>
      </input>
      <output type='ignition.msgs.Twist' topic='/cmd_vel'>linear: {x: 0.0}, angular: {z: 0.5}</output>
    </plugin>
    <physics name='1ms' type='ignored'>
      <max_step_size>0.001</max_step_size>
      <real_time_factor>1</real_time_factor>
      <real_time_update_rate>1000</real_time_update_rate>
    </physics>
    <plugin name='ignition::gazebo::systems::Physics' filename='libignition-gazebo-physics-system.so'/>
    <plugin name='ignition::gazebo::systems::UserCommands' filename='libignition-gazebo-user-commands-system.so'/>
    <plugin name='ignition::gazebo::systems::SceneBroadcaster' filename='libignition-gazebo-scene-broadcaster-system.so'/>
    <plugin
      filename="libignition-gazebo-sensors-system.so"
      name="ignition::gazebo::systems::Sensors">
      <render_engine>ogre2</render_engine>
    </plugin>
    <gravity>0 0 -9.8</gravity>
    <magnetic_field>6e-06 2.3e-05 -4.2e-05</magnetic_field>
    <atmosphere type='adiabatic'/>
    <scene>
      <ambient>0.4 0.4 0.4 1</ambient>
      <background>0.7 0.7 0.7 1</background>
      <shadows>true</shadows>
    </scene>
    <model name='ground_plane'>
      <static>true</static>
      <link name='link'>
        <collision name='collision'>
          <geometry>
            <plane>
              <normal>0 0 1</normal>
              <size>1 1</size>
            </plane>
          </geometry>
          <surface>
            <friction>
              <ode/>
            </friction>
            <bounce/>
            <contact/>
          </surface>
        </collision>
        <visual name='visual'>
          <geometry>
            <plane>
              <normal>0 0 1</normal>
              <size>100 100</size>
            </plane>
          </geometry>
          <material>
            <ambient>0.8 0.8 0.8 1</ambient>
            <diffuse>0.8 0.8 0.8 1</diffuse>
            <specular>0.8 0.8 0.8 1</specular>
          </material>
        </visual>
        <pose>0 0 0 0 -0 0</pose>
        <inertial>
          <pose>0 0 0 0 -0 0</pose>
          <mass>1</mass>
          <inertia>
            <ixx>1</ixx>
            <ixy>0</ixy>
            <ixz>0</ixz>
            <iyy>1</iyy>
            <iyz>0</iyz>
            <izz>1</izz>
          </inertia>
        </inertial>
        <enable_wind>false</enable_wind>
      </link>
      <pose>0 0 0 0 -0 0</pose>
      <self_collide>false</self_collide>
    </model>
    <model name='mrs_hudson' canonical_link='base_link'>
      <pose>0.992658 -0.677928 0.001139 -2e-06 -0.225697 1.54908</pose>
      <link name='base_link'>
        <pose>0 0 0.04 0 -0 0</pose>
        <inertial>
          <mass>3.6423399999999999</mass>
          <inertia>
            <ixx>0.018581199999999999</ixx>
            <ixy>7.5795199999999997e-06</ixy>
            <ixz>-4.0111200000000003e-05</ixz>
            <iyy>0.018703399999999998</iyy>
            <iyz>3.4509199999999999e-09</iyz>
            <izz>0.0172725</izz>
          </inertia>
          <origin rpy='0 0 0' xyz='0 0 0.15487131491131'/>
          <pose>0 0 0 0 -0 0</pose>
        </inertial>
        <visual name='visual'>
          <geometry>
            <mesh>
              <uri>file:///home/saurabh42/erc_ws/src/mrs_hudson/meshes/base_link.stl</uri>
            </mesh>
          </geometry>
          <material>
            <ambient>0.5 0 0.5 1</ambient>
            <diffuse>0.5 0 0.5 1</diffuse>
            <specular>0.5 0 0.5 0.5</specular>
          </material>
          <origin rpy='0 0 0' xyz='0 0 0'/>
        </visual>
        <collision name='collision'>
          <geometry>
            <mesh>
              <uri>file:///home/saurabh42/erc_ws/src/mrs_hudson/meshes/base_link.stl</uri>
            </mesh>
          </geometry>
          <origin rpy='0 0 0' xyz='0 0 0'/>
        </collision>
        <enable_wind>false</enable_wind>
        <sensor name='gpu_lidar' type='gpu_lidar'>"
          <pose relative_to='lidar_frame'>0 0 0 0 0 0</pose>
          <topic>lidar</topic>
          <update_rate>10</update_rate>
          <ray>
              <scan>
                  <horizontal>
                      <samples>640</samples>
                      <resolution>1</resolution>
                      <min_angle>-1.396263</min_angle>
                      <max_angle>1.396263</max_angle>
                  </horizontal>
                  <vertical>
                      <samples>1</samples>
                      <resolution>0.01</resolution>
                      <min_angle>0</min_angle>
                      <max_angle>0</max_angle>
                  </vertical>
              </scan>
              <range>
                  <min>0.08</min>
                  <max>10.0</max>
                  <resolution>0.01</resolution>
              </range>
          </ray>
          <always_on>1</always_on>
          <visualize>true</visualize>
      </sensor>
      <sensor name="depth_camera" type="depth_camera">
          <camera>
            <horizontal_fov>1.047</horizontal_fov>
            <image>
              <width>320</width>
              <height>240</height>
              <format>R_FLOAT32</format>
            </image>
            <clip>
              <near>0.1</near>
              <far>100</far>
            </clip>
          </camera>
          <always_on>1</always_on>
          <update_rate>10</update_rate>
          <visualize>true</visualize>
          <topic>depth_camera</topic>
          <plugin
            filename="RosGzPointCloud"
            name="ros_gz_point_cloud::PointCloud">
            <topic>points</topic>
            <frame_id>map</frame_id>
          </plugin>
        </sensor>
      </link>
      <frame name="lidar_frame" attached_to='base_link'>
        <pose>0 0 0.2 0 0 0</pose>
      </frame>
      <link name='left_wheel'>
        <pose>0 0.0591 0.04 1.57089 -0.192087 3.14159</pose>
        <inertial>
          <mass>0.0072782699999999999</mass>
          <inertia>
            <ixx>2.8024699999999999e-06</ixx>
            <ixy>-2.5770800000000002e-10</ixy>
            <ixz>-4.5088299999999998e-21</ixz>
            <iyy>2.8010899999999999e-06</iyy>
            <iyz>-1.13354e-19</iyz>
            <izz>4.9515500000000001e-06</izz>
          </inertia>
          <origin rpy='0 0 0' xyz='0 0 0'/>
          <pose>0 0 0 0 -0 0</pose>
        </inertial>
        <visual name='visual'>
          <geometry>
            <mesh>
              <uri>file:///home/saurabh42/erc_ws/src/mrs_hudson/meshes/left_wheel.stl</uri>
            </mesh>
          </geometry>
          <material>
            <ambient>0 0 0 1</ambient>
            <diffuse>0 0 0 1</diffuse>
            <specular>0 0 0 1</specular>
          </material>
          <origin rpy='0 0 0' xyz='0 0 0'/>
        </visual>
        <collision name='collision'>
          <geometry>
            <mesh>
              <uri>file:///home/saurabh42/erc_ws/src/mrs_hudson/meshes/left_wheel.stl</uri>
            </mesh>
          </geometry>
          <origin rpy='0 0 0' xyz='0 0 0'/>
        </collision>
        <enable_wind>false</enable_wind>
      </link>
      <link name='right_wheel'>
        <pose>0 -0.0591 0.04 -1.5707 0.469429 0</pose>
        <inertial>
          <mass>0.0072782699999999999</mass>
          <inertia>
            <ixx>2.8024699999999999e-06</ixx>
            <ixy>2.5770800000000002e-10</ixy>
            <ixz>-8.1125200000000004e-22</ixz>
            <iyy>2.8010899999999999e-06</iyy>
            <iyz>6.6888400000000002e-21</iyz>
            <izz>4.9515500000000001e-06</izz>
          </inertia>
          <origin rpy='0 0 0' xyz='0 0 0'/>
          <pose>0 0 0 0 -0 0</pose>
        </inertial>
        <visual name='visual'>
          <geometry>
            <mesh>
              <uri>file:///home/saurabh42/erc_ws/src/mrs_hudson/meshes/right_wheel.stl</uri>
            </mesh>
          </geometry>
          <material>
            <ambient>0 0 0 1</ambient>
            <diffuse>0 0 0 1</diffuse>
            <specular>0 0 0 1</specular>
          </material>
          <origin rpy='0 0 0' xyz='0 0 0'/>
        </visual>
        <collision name='collision'>
          <geometry>
            <mesh>
              <uri>file:///home/saurabh42/erc_ws/src/mrs_hudson/meshes/right_wheel.stl</uri>
            </mesh>
          </geometry>
          <origin rpy='0 0 0' xyz='0 0 0'/>
        </collision>
        <enable_wind>false</enable_wind>
      </link>
      <joint name='left_wheel_joint' type='revolute'>
        <pose>0 -0 0 0 -0 0</pose>
        <parent>base_link</parent>
        <child>left_wheel</child>
        <axis>
          <xyz>0 9.6e-05 1</xyz>
          <limit>
            <lower>-1.7976900000000001e+308</lower>
            <upper>1.7976900000000001e+308</upper>
            <effort>inf</effort>
            <velocity>inf</velocity>
            <stiffness>100000000</stiffness>
            <dissipation>1</dissipation>
          </limit>
          <dynamics>
            <spring_reference>0</spring_reference>
            <spring_stiffness>0</spring_stiffness>
            <damping>0</damping>
            <friction>0</friction>
          </dynamics>
        </axis>
      </joint>
      <joint name='right_wheel_joint' type='revolute'>
        <pose>0 0 0 0 -0 0</pose>
        <parent>base_link</parent>
        <child>right_wheel</child>
        <axis>
          <xyz>0 9.6e-05 1</xyz>
          <limit>
            <lower>-1.7976900000000001e+308</lower>
            <upper>1.7976900000000001e+308</upper>
            <effort>inf</effort>
            <velocity>inf</velocity>
            <stiffness>100000000</stiffness>
            <dissipation>1</dissipation>
          </limit>
          <dynamics>
            <spring_reference>0</spring_reference>
            <spring_stiffness>0</spring_stiffness>
            <damping>0</damping>
            <friction>0</friction>
          </dynamics>
        </axis>
      </joint>
      <plugin name='ignition::gazebo::systems::DiffDrive' filename='libignition-gazebo-diff-drive-system.so'>
        <left_joint>left_wheel_joint</left_joint>
        <right_joint>right_wheel_joint</right_joint>
        <wheel_separation>0.1182</wheel_separation>
        <wheel_radius>0.04</wheel_radius>
        <odom_publish_frequency>1</odom_publish_frequency>
        <topic>cmd_vel</topic>
      </plugin>
      <static>false</static>
      <self_collide>false</self_collide>
    </model>
    <light name='sun' type='directional'>
      <pose>0 0 10 0 -0 0</pose>
      <cast_shadows>true</cast_shadows>
      <intensity>1</intensity>
      <direction>-0.5 0.1 -0.9</direction>
      <diffuse>0.8 0.8 0.8 1</diffuse>
      <specular>0.2 0.2 0.2 1</specular>
      <attenuation>
        <range>1000</range>
        <linear>0.01</linear>
        <constant>0.90000000000000002</constant>
        <quadratic>0.001</quadratic>
      </attenuation>
      <spot>
        <inner_angle>0</inner_angle>
        <outer_angle>0</outer_angle>
        <falloff>0</falloff>
      </spot>
    </light>
  </world>
</sdf>
